2021-05-18 14:41:43,544 ERROR: Exception on /user/123 [GET] [in c:\users\ÀÌÁöÈÆ\desktop\miguel\microblog\venv\lib\site-packages\flask\app.py:1891]
Traceback (most recent call last):
  File "c:\users\ÀÌÁöÈÆ\desktop\miguel\microblog\venv\lib\site-packages\sqlalchemy\engine\base.py", line 1706, in _execute_context
    self.dialect.do_execute(
  File "c:\users\ÀÌÁöÈÆ\desktop\miguel\microblog\venv\lib\site-packages\sqlalchemy\engine\default.py", line 717, in do_execute
    cursor.execute(statement, parameters)
sqlite3.OperationalError: no such table: followers

The above exception was the direct cause of the following exception:

Traceback (most recent call last):
  File "c:\users\ÀÌÁöÈÆ\desktop\miguel\microblog\venv\lib\site-packages\flask\app.py", line 2447, in wsgi_app
    response = self.full_dispatch_request()
  File "c:\users\ÀÌÁöÈÆ\desktop\miguel\microblog\venv\lib\site-packages\flask\app.py", line 1952, in full_dispatch_request
    rv = self.handle_user_exception(e)
  File "c:\users\ÀÌÁöÈÆ\desktop\miguel\microblog\venv\lib\site-packages\flask\app.py", line 1821, in handle_user_exception
    reraise(exc_type, exc_value, tb)
  File "c:\users\ÀÌÁöÈÆ\desktop\miguel\microblog\venv\lib\site-packages\flask\_compat.py", line 39, in reraise
    raise value
  File "c:\users\ÀÌÁöÈÆ\desktop\miguel\microblog\venv\lib\site-packages\flask\app.py", line 1950, in full_dispatch_request
    rv = self.dispatch_request()
  File "c:\users\ÀÌÁöÈÆ\desktop\miguel\microblog\venv\lib\site-packages\flask\app.py", line 1936, in dispatch_request
    return self.view_functions[rule.endpoint](**req.view_args)
  File "c:\users\ÀÌÁöÈÆ\desktop\miguel\microblog\venv\lib\site-packages\flask_login\utils.py", line 272, in decorated_view
    return func(*args, **kwargs)
  File "C:\Users\ÀÌÁöÈÆ\Desktop\miguel\microblog\app\routes.py", line 141, in user
    return render_template('user.html', user=user, posts=posts.items,
  File "c:\users\ÀÌÁöÈÆ\desktop\miguel\microblog\venv\lib\site-packages\flask\templating.py", line 137, in render_template
    return _render(
  File "c:\users\ÀÌÁöÈÆ\desktop\miguel\microblog\venv\lib\site-packages\flask\templating.py", line 120, in _render
    rv = template.render(context)
  File "c:\users\ÀÌÁöÈÆ\desktop\miguel\microblog\venv\lib\site-packages\jinja2\environment.py", line 1090, in render
    self.environment.handle_exception()
  File "c:\users\ÀÌÁöÈÆ\desktop\miguel\microblog\venv\lib\site-packages\jinja2\environment.py", line 832, in handle_exception
    reraise(*rewrite_traceback_stack(source=source))
  File "c:\users\ÀÌÁöÈÆ\desktop\miguel\microblog\venv\lib\site-packages\jinja2\_compat.py", line 28, in reraise
    raise value.with_traceback(tb)
  File "C:\Users\ÀÌÁöÈÆ\Desktop\miguel\microblog\app\templates\user.html", line 1, in top-level template code
    {% extends "base.html" %}
  File "C:\Users\ÀÌÁöÈÆ\Desktop\miguel\microblog\app\templates\base.html", line 1, in top-level template code
    {% extends 'bootstrap/base.html' %}
  File "c:\users\ÀÌÁöÈÆ\desktop\miguel\microblog\venv\lib\site-packages\flask_bootstrap\templates\bootstrap\base.html", line 1, in top-level template code
    {% block doc -%}
  File "c:\users\ÀÌÁöÈÆ\desktop\miguel\microblog\venv\lib\site-packages\flask_bootstrap\templates\bootstrap\base.html", line 4, in block "doc"
    {%- block html %}
  File "c:\users\ÀÌÁöÈÆ\desktop\miguel\microblog\venv\lib\site-packages\flask_bootstrap\templates\bootstrap\base.html", line 20, in block "html"
    {% block body -%}
  File "c:\users\ÀÌÁöÈÆ\desktop\miguel\microblog\venv\lib\site-packages\flask_bootstrap\templates\bootstrap\base.html", line 23, in block "body"
    {% block content -%}
  File "C:\Users\ÀÌÁöÈÆ\Desktop\miguel\microblog\app\templates\base.html", line 48, in block "content"
    {% block app_content %}{% endblock %}
  File "C:\Users\ÀÌÁöÈÆ\Desktop\miguel\microblog\app\templates\user.html", line 13, in block "app_content"
    <p>{{ _('%(count)d followers', count=user.followers.count()) }}, {{ _('%(count)d following', count=user.followed.count()) }}</p>
  File "c:\users\ÀÌÁöÈÆ\desktop\miguel\microblog\venv\lib\site-packages\sqlalchemy\orm\dynamic.py", line 337, in count
    return self._generate(sess).count()
  File "c:\users\ÀÌÁöÈÆ\desktop\miguel\microblog\venv\lib\site-packages\sqlalchemy\orm\query.py", line 3078, in count
    return self._from_self(col).enable_eagerloads(False).scalar()
  File "c:\users\ÀÌÁöÈÆ\desktop\miguel\microblog\venv\lib\site-packages\sqlalchemy\orm\query.py", line 2819, in scalar
    ret = self.one()
  File "c:\users\ÀÌÁöÈÆ\desktop\miguel\microblog\venv\lib\site-packages\sqlalchemy\orm\query.py", line 2796, in one
    return self._iter().one()
  File "c:\users\ÀÌÁöÈÆ\desktop\miguel\microblog\venv\lib\site-packages\sqlalchemy\orm\query.py", line 2834, in _iter
    result = self.session.execute(
  File "c:\users\ÀÌÁöÈÆ\desktop\miguel\microblog\venv\lib\site-packages\sqlalchemy\orm\session.py", line 1675, in execute
    result = conn._execute_20(statement, params or {}, execution_options)
  File "c:\users\ÀÌÁöÈÆ\desktop\miguel\microblog\venv\lib\site-packages\sqlalchemy\engine\base.py", line 1521, in _execute_20
    return meth(self, args_10style, kwargs_10style, execution_options)
  File "c:\users\ÀÌÁöÈÆ\desktop\miguel\microblog\venv\lib\site-packages\sqlalchemy\sql\elements.py", line 313, in _execute_on_connection
    return connection._execute_clauseelement(
  File "c:\users\ÀÌÁöÈÆ\desktop\miguel\microblog\venv\lib\site-packages\sqlalchemy\engine\base.py", line 1390, in _execute_clauseelement
    ret = self._execute_context(
  File "c:\users\ÀÌÁöÈÆ\desktop\miguel\microblog\venv\lib\site-packages\sqlalchemy\engine\base.py", line 1749, in _execute_context
    self._handle_dbapi_exception(
  File "c:\users\ÀÌÁöÈÆ\desktop\miguel\microblog\venv\lib\site-packages\sqlalchemy\engine\base.py", line 1930, in _handle_dbapi_exception
    util.raise_(
  File "c:\users\ÀÌÁöÈÆ\desktop\miguel\microblog\venv\lib\site-packages\sqlalchemy\util\compat.py", line 211, in raise_
    raise exception
  File "c:\users\ÀÌÁöÈÆ\desktop\miguel\microblog\venv\lib\site-packages\sqlalchemy\engine\base.py", line 1706, in _execute_context
    self.dialect.do_execute(
  File "c:\users\ÀÌÁöÈÆ\desktop\miguel\microblog\venv\lib\site-packages\sqlalchemy\engine\default.py", line 717, in do_execute
    cursor.execute(statement, parameters)
sqlalchemy.exc.OperationalError: (sqlite3.OperationalError) no such table: followers
[SQL: SELECT count(*) AS count_1 
FROM (SELECT user.id AS user_id, user.username AS user_username, user.email AS user_email, user.password_hash AS user_password_hash, user.about_me AS user_about_me, user.last_seen AS user_last_seen 
FROM user, followers 
WHERE followers.followed_id = ? AND followers.follower_id = user.id) AS anon_1]
[parameters: (1,)]
(Background on this error at: http://sqlalche.me/e/14/e3q8)
